Traceback (most recent call last):
  File "/Users/heyanan/crazy_code/note_pycharm/chapter07/python异常传播轨迹_7_4.py", line 28, in <module>
    main()
  File "/Users/heyanan/crazy_code/note_pycharm/chapter07/python异常传播轨迹_7_4.py", line 12, in main
    fistMethod()
  File "/Users/heyanan/crazy_code/note_pycharm/chapter07/python异常传播轨迹_7_4.py", line 16, in fistMethod
    secondMethod()
  File "/Users/heyanan/crazy_code/note_pycharm/chapter07/python异常传播轨迹_7_4.py", line 20, in secondMethod
    thirdMethod()
  File "/Users/heyanan/crazy_code/note_pycharm/chapter07/python异常传播轨迹_7_4.py", line 24, in thirdMethod
    raise SelfException("自定义异常信息")
SelfException: 自定义异常信息
